Workbook

Sheet Cover
B2: freeitsm
B3: Functionality Inventory & Comprehensive Test Plan
B5: The complete surface of the platform: what shipped before this development cycle, what was added across Phases 8-11 plus the KPI and Customers modules, what Phases 12-14 added to the ticket experience and customer depth, and an executable test plan to verify every module end to end.
B9: Stack | C9: PHP - MySQL - Docker
B10: Auth models | C10: Analysts (staff) and portal users (end users)
B11: Scope | C11: Original baseline (Phases 1-7 + base app), Phases 8-11, KPI, Customers, polish, data export, mass import, LMS training & journal, Phases 12-14 (reading pane, time tracking, category hierarchy, customer contacts, portal user links, knowledge KPIs), BI export, demo history, migration, inbound webhooks
B12: Deferred | C12: 10c SAML, 10d channels, 11c rota cross-check, 11e TOIL, 14b KPI help page - NOT built, do not test
B14: Workbook contents
B15: Test Plan | C15: The executable suites - one row per test case. Fill the Status / Tester / Date / Notes columns.
B16: Summary | C16: Auto-calculating pass/fail totals (overall and per suite). Do not edit - it reads Test Plan.
B17: Original Functionality | C17: Inventory of the pre-cycle baseline, by module.
B18: Added (8-11) | C18: Every feature added this cycle, phase by phase - including the KPI (K0-K3) and Customers modules.
B19: Deferred | C19: Explicitly out of scope - no code exists.
B20: Added (12-14) | C20: Everything added after the 8-11 cycle: the ticket experience, customer depth, knowledge KPIs, BI export, demo history, migration and inbound webhooks.
B21: How to use
B22: Only edit the four yellow columns on Test Plan: Status, Tester, Date, Notes. Status is a dropdown.
B23: Status values: Not run / Pass / Fail / Blocked / N/A. Leave N/A where a case doesn't apply (e.g. tenancy on a single-company install).
B25: Example of a completed row (for format only):
B26: Test ID | C26: Status | D26: Tester | E26: Date | F26: Notes
B27: S3-02 | C27: Pass | D27: J. Phillips | E27: 2026-07-22 | F27: Verified on staging; audit trail correct
B29: Generated by the freeitsm dev cycle handoff. Load database/demo-csv/ via System > Mass import first (suite 24) for a populated system to test against.

Sheet Test Plan
A1: Suite | B1: Test ID | C1: Area | D1: Type | E1: Phase | F1: Steps | G1: Expected result | H1: Status | I1: Tester | J1: Date | K1: Notes
A2: 0 Setup | B2: S0-01 | C2: Environment | D2: Setup | E2: - | F2: Deploy the branch and run Database Verify (api/system/db_verify.php) as an admin. | G2: Reports created tables/columns with NO errors: ticket_sla_snapshot, scheduled_report, change_freeze_windows, change_cmdb_objects, contract_assets, assets.end_of_life_date/disposal_date/disposal_method, analysts.manager_id, overtime_requests/audit/settings (+5 seeded settings). | H2: Not run
A3: 0 Setup | B3: S0-02 | C3: Environment | D3: New | E3: 8a | F3: Run cron/sla_snapshot_rebuild.php?token=<sla_cron_token> once. | G3: Returns processed/tracked counts; ticket_sla_snapshot populated. | H3: Not run
A4: 0 Setup | B4: S0-03 | C4: Environment | D4: Mixed | E4: - | F4: Confirm cron jobs scheduled: sla_breach_check (~5m), scheduled_reports (hourly), workflow_scheduled (hourly), sla_snapshot_rebuild (nightly). | G4: Each runs and logs; no auth/lockout errors. | H4: Not run
A5: 0 Setup | B5: S0-04 | C5: Environment | D5: Setup | E5: - | F5: Ensure at least one active mailbox is configured. | G5: Test send from mailbox settings succeeds (needed for report/notify email tests). | H5: Not run
A6: 0 Setup | B6: S0-05 | C6: Environment | D6: Setup | E6: - | F6: Create a 2nd company; analyst A (company 1 only), analyst B (company 2 only), plus an admin. | G6: Needed for the tenancy suite. Single-company installs: tenancy cases are N/A. | H6: Not run
A7: 0 Setup | B7: S0-06 | C7: Environment | D7: New | E7: KPI/Cu | F7: Run Database Verify (api/system/db_verify.php) again after this batch and read the KPI / Customer section. | G7: Creates with NO errors: kpi_definitions (+69 seeded metrics), kpi_measurements, ticket_streams (+NOC/SOC seed), ticket_escalations, ticket_hold_events, ticket_qa_reviews, customers, customer_cmdb_objects; columns tickets.stream_id / playbook_eligible / acknowledged_datetime / customer_id and analysts.tier / loaded_rate / contracted_weekly_hours; keys fk_tickets_customer, fk_tickets_stream, fk_customers_tenant, uq_customer_cmdb. | H7: Not run
A8: 0 Setup | B8: S0-07 | C8: Environment | D8: New | E8: K1/K3 | F8: System > Analysts: set tier (L1/L2/L3) on every active analyst, plus loaded_rate (loaded hourly cost) and contracted_weekly_hours. | G8: All three save per analyst. A ticket's tier is its OWNER's tier, so any analyst left without a tier keeps their tickets out of the tier scorecards (expected, not a bug). | H8: Not run
A9: 0 Setup | B9: S0-08 | C9: Environment | D9: New | E9: K2 | F9: Run cron/kpi_snapshot.php?token=<sla_cron_token> once for the current month. | G9: Prints "KPI snapshot (YYYY-MM) done" with Computed / Skipped (manual/feed) / Errors, and Errors: 0. sla_cron_runs logs one run whose notes start with [kpi-snapshot]. | H9: Not run
A10: 0 Setup | B10: S0-09 | C10: Environment | D10: New | E10: Polish | F10: Run Database Verify once more after the polish batch. | G10: Adds contracts.service_hours / response_sla / resolution_sla / coverage_notes and the change_freeze_scopes table (+ uq_change_freeze_scope and the cascade FK to change_freeze_windows), with no errors. | H10: Not run
A11: 0 Setup | B11: S0-10 | C11: Environment | D11: New | E11: Export/LMS | F11: Run Database Verify after the export / LMS batch. | G11: Creates with no errors: lms_certifications, analyst_certifications, analyst_training_records, analyst_journal_entries, with their indexes and FKs (cascade on analyst, SET NULL on catalogue entry / course / journal author). No schema change is needed for the data export — it reads the live schema. | H11: Not run
A12: 1 Access & security | B12: S1-01 | C12: Auth | D12: Baseline | E12: - | F12: Log in with correct password; then wrong password x N. | G12: Success routes to app; repeated failures increment lockout (failed_login_count / locked_until). | H12: Not run
A13: 1 Access & security | B13: S1-02 | C13: Auth | D13: Baseline | E13: - | F13: Enable MFA/TOTP; log out/in; test 'trust this device'. | G13: OTP prompted; correct code admits; trusted device skips OTP next time. | H13: Not run
... A304: 35 Inbound webhooks | B304: S35-06 | C304: Webhooks | D304: Mixed | E304: 12c | F304: Raise a ticket through an inbound webhook and check its ticket type. | G304: Confirm the intended behaviour: monitoring-raised tickets are the case the new Event type exists for. Record what happens today - the two features have not been wired together. | H304: Not run

Sheet Summary
B2: Test execution summary
B3: Live totals from the Test Plan sheet. Do not edit.
B5: Status | C5: Count | D5: % of total
B6: Pass | C6: =COUNTIF('Test Plan'!$H$2:$H$304,"Pass") | D6: =IFERROR(C6/$C$11,0)
B7: Fail | C7: =COUNTIF('Test Plan'!$H$2:$H$304,"Fail") | D7: =IFERROR(C7/$C$11,0)
B8: Blocked | C8: =COUNTIF('Test Plan'!$H$2:$H$304,"Blocked") | D8: =IFERROR(C8/$C$11,0)
B9: Not run | C9: =COUNTIF('Test Plan'!$H$2:$H$304,"Not run") | D9: =IFERROR(C9/$C$11,0)
B10: N/A | C10: =COUNTIF('Test Plan'!$H$2:$H$304,"N/A") | D10: =IFERROR(C10/$C$11,0)
B11: Total cases | C11: =COUNTA('Test Plan'!$B$2:$B$304)
B13: Tested (excl. Not run) | C13: =C6+C7+C8+C10
B14: Pass rate (of executed Pass/Fail) | C14: =IFERROR(C6/(C6+C7),0)
B16: By suite
B17: Suite | C17: Cases | D17: Pass | E17: Fail | F17: Blocked | G17: Not run | H17: N/A
B18: 0 Setup | C18: =COUNTIF('Test Plan'!$A$2:$A$304,"0 Setup") | D18: =COUNTIFS('Test Plan'!$A$2:$A$304,"0 Setup",'Test Plan'!$H$2:$H$304,"Pass") | E18: =COUNTIFS('Test Plan'!$A$2:$A$304,"0 Setup",'Test Plan'!$H$2:$H$304,"Fail") | F18: =COUNTIFS('Test Plan'!$A$2:$A$304,"0 Setup",'Test Plan'!$H$2:$H$304,"Blocked") | G18: =COUNTIFS('Test Plan'!$A$2:$A$304,"0 Setup",'Test Plan'!$H$2:$H$304,"Not run") | H18: =COUNTIFS('Test Plan'!$A$2:$A$304,"0 Setup",'Test Plan'!$H$2:$H$304,"N/A")
B19: 1 Access & security | C19: =COUNTIF('Test Plan'!$A$2:$A$304,"1 Access & security") | D19: =COUNTIFS('Test Plan'!$A$2:$A$304,"1 Access & security",'Test Plan'!$H$2:$H$304,"Pass") | E19: =COUNTIFS('Test Plan'!$A$2:$A$304,"1 Access & security",'Test Plan'!$H$2:$H$304,"Fail") | F19: =COUNTIFS('Test Plan'!$A$2:$A$304,"1 Access & security",'Test Plan'!$H$2:$H$304,"Blocked") | G19: =COUNTIFS('Test Plan'!$A$2:$A$304,"1 Access & security",'Test Plan'!$H$2:$H$304,"Not run") | H19: =COUNTIFS('Test Plan'!$A$2:$A$304,"1 Access & security",'Test Plan'!$H$2:$H$304,"N/A")
B20: 2 Multi-tenancy | C20: =COUNTIF('Test Plan'!$A$2:$A$304,"2 Multi-tenancy") | D20: =COUNTIFS('Test Plan'!$A$2:$A$304,"2 Multi-tenancy",'Test Plan'!$H$2:$H$304,"Pass") | E20: =COUNTIFS('Test Plan'!$A$2:$A$304,"2 Multi-tenancy",'Test Plan'!$H$2:$H$304,"Fail") | F20: =COUNTIFS('Test Plan'!$A$2:$A$304,"2 Multi-tenancy",'Test Plan'!$H$2:$H$304,"Blocked") | G20: =COUNTIFS('Test Plan'!$A$2:$A$304,"2 Multi-tenancy",'Test Plan'!$H$2:$H$304,"Not run") | H20: =COUNTIFS('Test Plan'!$A$2:$A$304,"2 Multi-tenancy",'Test Plan'!$H$2:$H$304,"N/A")
B21: 3 Tickets | C21: =COUNTIF('Test Plan'!$A$2:$A$304,"3 Tickets") | D21: =COUNTIFS('Test Plan'!$A$2:$A$304,"3 Tickets",'Test Plan'!$H$2:$H$304,"Pass") | E21: =COUNTIFS('Test Plan'!$A$2:$A$304,"3 Tickets",'Test Plan'!$H$2:$H$304,"Fail") | F21: =COUNTIFS('Test Plan'!$A$2:$A$304,"3 Tickets",'Test Plan'!$H$2:$H$304,"Blocked") | G21: =COUNTIFS('Test Plan'!$A$2:$A$304,"3 Tickets",'Test Plan'!$H$2:$H$304,"Not run") | H21: =COUNTIFS('Test Plan'!$A$2:$A$304,"3 Tickets",'Test Plan'!$H$2:$H$304,"N/A")
B22: 4 SLA & snapshot | C22: =COUNTIF('Test Plan'!$A$2:$A$304,"4 SLA & snapshot") | D22: =COUNTIFS('Test Plan'!$A$2:$A$304,"4 SLA & snapshot",'Test Plan'!$H$2:$H$304,"Pass") | E22: =COUNTIFS('Test Plan'!$A$2:$A$304,"4 SLA & snapshot",'Test Plan'!$H$2:$H$304,"Fail") | F22: =COUNTIFS('Test Plan'!$A$2:$A$304,"4 SLA & snapshot",'Test Plan'!$H$2:$H$304,"Blocked") | G22: =COUNTIFS('Test Plan'!$A$2:$A$304,"4 SLA & snapshot",'Test Plan'!$H$2:$H$304,"Not run") | H22: =COUNTIFS('Test Plan'!$A$2:$A$304,"4 SLA & snapshot",'Test Plan'!$H$2:$H$304,"N/A")
B23: 5 Reporting | C23: =COUNTIF('Test Plan'!$A$2:$A$304,"5 Reporting") | D23: =COUNTIFS('Test Plan'!$A$2:$A$304,"5 Reporting",'Test Plan'!$H$2:$H$304,"Pass") | E23: =COUNTIFS('Test Plan'!$A$2:$A$304,"5 Reporting",'Test Plan'!$H$2:$H$304,"Fail") | F23: =COUNTIFS('Test Plan'!$A$2:$A$304,"5 Reporting",'Test Plan'!$H$2:$H$304,"Blocked") | G23: =COUNTIFS('Test Plan'!$A$2:$A$304,"5 Reporting",'Test Plan'!$H$2:$H$304,"Not run") | H23: =COUNTIFS('Test Plan'!$A$2:$A$304,"5 Reporting",'Test Plan'!$H$2:$H$304,"N/A")
B24: 6 Assets | C24: =COUNTIF('Test Plan'!$A$2:$A$304,"6 Assets") | D24: =COUNTIFS('Test Plan'!$A$2:$A$304,"6 Assets",'Test Plan'!$H$2:$H$304,"Pass") | E24: =COUNTIFS('Test Plan'!$A$2:$A$304,"6 Assets",'Test Plan'!$H$2:$H$304,"Fail") | F24: =COUNTIFS('Test Plan'!$A$2:$A$304,"6 Assets",'Test Plan'!$H$2:$H$304,"Blocked") | G24: =COUNTIFS('Test Plan'!$A$2:$A$304,"6 Assets",'Test Plan'!$H$2:$H$304,"Not run") | H24: =COUNTIFS('Test Plan'!$A$2:$A$304,"6 Assets",'Test Plan'!$H$2:$H$304,"N/A")
B25: 7 Software | C25: =COUNTIF('Test Plan'!$A$2:$A$304,"7 Software") | D25: =COUNTIFS('Test Plan'!$A$2:$A$304,"7 Software",'Test Plan'!$H$2:$H$304,"Pass") | E25: =COUNTIFS('Test Plan'!$A$2:$A$304,"7 Software",'Test Plan'!$H$2:$H$304,"Fail") | F25: =COUNTIFS('Test Plan'!$A$2:$A$304,"7 Software",'Test Plan'!$H$2:$H$304,"Blocked") | G25: =COUNTIFS('Test Plan'!$A$2:$A$304,"7 Software",'Test Plan'!$H$2:$H$304,"Not run") | H25: =COUNTIFS('Test Plan'!$A$2:$A$304,"7 Software",'Test Plan'!$H$2:$H$304,"N/A")
B26: 8 Changes | C26: =COUNTIF('Test Plan'!$A$2:$A$304,"8 Changes") | D26: =COUNTIFS('Test Plan'!$A$2:$A$304,"8 Changes",'Test Plan'!$H$2:$H$304,"Pass") | E26: =COUNTIFS('Test Plan'!$A$2:$A$304,"8 Changes",'Test Plan'!$H$2:$H$304,"Fail") | F26: =COUNTIFS('Test Plan'!$A$2:$A$304,"8 Changes",'Test Plan'!$H$2:$H$304,"Blocked") | G26: =COUNTIFS('Test Plan'!$A$2:$A$304,"8 Changes",'Test Plan'!$H$2:$H$304,"Not run") | H26: =COUNTIFS('Test Plan'!$A$2:$A$304,"8 Changes",'Test Plan'!$H$2:$H$304,"N/A")
B27: 9 Problems | C27: =COUNTIF('Test Plan'!$A$2:$A$304,"9 Problems") | D27: =COUNTIFS('Test Plan'!$A$2:$A$304,"9 Problems",'Test Plan'!$H$2:$H$304,"Pass") | E27: =COUNTIFS('Test Plan'!$A$2:$A$304,"9 Problems",'Test Plan'!$H$2:$H$304,"Fail") | F27: =COUNTIFS('Test Plan'!$A$2:$A$304,"9 Problems",'Test Plan'!$H$2:$H$304,"Blocked") | G27: =COUNTIFS('Test Plan'!$A$2:$A$304,"9 Problems",'Test Plan'!$H$2:$H$304,"Not run") | H27: =COUNTIFS('Test Plan'!$A$2:$A$304,"9 Problems",'Test Plan'!$H$2:$H$304,"N/A")
B28: 10 CMDB | C28: =COUNTIF('Test Plan'!$A$2:$A$304,"10 CMDB") | D28: =COUNTIFS('Test Plan'!$A$2:$A$304,"10 CMDB",'Test Plan'!$H$2:$H$304,"Pass") | E28: =COUNTIFS('Test Plan'!$A$2:$A$304,"10 CMDB",'Test Plan'!$H$2:$H$304,"Fail") | F28: =COUNTIFS('Test Plan'!$A$2:$A$304,"10 CMDB",'Test Plan'!$H$2:$H$304,"Blocked") | G28: =COUNTIFS('Test Plan'!$A$2:$A$304,"10 CMDB",'Test Plan'!$H$2:$H$304,"Not run") | H28: =COUNTIFS('Test Plan'!$A$2:$A$304,"10 CMDB",'Test Plan'!$H$2:$H$304,"N/A")
B29: 11 Contracts | C29: =COUNTIF('Test Plan'!$A$2:$A$304,"11 Contracts") | D29: =COUNTIFS('Test Plan'!$A$2:$A$304,"11 Contracts",'Test Plan'!$H$2:$H$304,"Pass") | E29: =COUNTIFS('Test Plan'!$A$2:$A$304,"11 Contracts",'Test Plan'!$H$2:$H$304,"Fail") | F29: =COUNTIFS('Test Plan'!$A$2:$A$304,"11 Contracts",'Test Plan'!$H$2:$H$304,"Blocked") | G29: =COUNTIFS('Test Plan'!$A$2:$A$304,"11 Contracts",'Test Plan'!$H$2:$H$304,"Not run") | H29: =COUNTIFS('Test Plan'!$A$2:$A$304,"11 Contracts",'Test Plan'!$H$2:$H$304,"N/A")
B30: 12 Other modules | C30: =COUNTIF('Test Plan'!$A$2:$A$304,"12 Other modules") | D30: =COUNTIFS('Test Plan'!$A$2:$A$304,"12 Other modules",'Test Plan'!$H$2:$H$304,"Pass") | E30: =COUNTIFS('Test Plan'!$A$2:$A$304,"12 Other modules",'Test Plan'!$H$2:$H$304,"Fail") | F30: =COUNTIFS('Test Plan'!$A$2:$A$304,"12 Other modules",'Test Plan'!$H$2:$H$304,"Blocked") | G30: =COUNTIFS('Test Plan'!$A$2:$A$304,"12 Other modules",'Test Plan'!$H$2:$H$304,"Not run") | H30: =COUNTIFS('Test Plan'!$A$2:$A$304,"12 Other modules",'Test Plan'!$H$2:$H$304,"N/A")
B31: 13 Workflow | C31: =COUNTIF('Test Plan'!$A$2:$A$304,"13 Workflow") | D31: =COUNTIFS('Test Plan'!$A$2:$A$304,"13 Workflow",'Test Plan'!$H$2:$H$304,"Pass") | E31: =COUNTIFS('Test Plan'!$A$2:$A$304,"13 Workflow",'Test Plan'!$H$2:$H$304,"Fail") | F31: =COUNTIFS('Test Plan'!$A$2:$A$304,"13 Workflow",'Test Plan'!$H$2:$H$304,"Blocked") | G31: =COUNTIFS('Test Plan'!$A$2:$A$304,"13 Workflow",'Test Plan'!$H$2:$H$304,"Not run") | H31: =COUNTIFS('Test Plan'!$A$2:$A$304,"13 Workflow",'Test Plan'!$H$2:$H$304,"N/A")
B32: 14 Overtime | C32: =COUNTIF('Test Plan'!$A$2:$A$304,"14 Overtime") | D32: =COUNTIFS('Test Plan'!$A$2:$A$304,"14 Overtime",'Test Plan'!$H$2:$H$304,"Pass") | E32: =COUNTIFS('Test Plan'!$A$2:$A$304,"14 Overtime",'Test Plan'!$H$2:$H$304,"Fail") | F32: =COUNTIFS('Test Plan'!$A$2:$A$304,"14 Overtime",'Test Plan'!$H$2:$H$304,"Blocked") | G32: =COUNTIFS('Test Plan'!$A$2:$A$304,"14 Overtime",'Test Plan'!$H$2:$H$304,"Not run") | H32: =COUNTIFS('Test Plan'!$A$2:$A$304,"14 Overtime",'Test Plan'!$H$2:$H$304,"N/A")
B33: 15 System admin | C33: =COUNTIF('Test Plan'!$A$2:$A$304,"15 System admin") | D33: =COUNTIFS('Test Plan'!$A$2:$A$304,"15 System admin",'Test Plan'!$H$2:$H$304,"Pass") | E33: =COUNTIFS('Test Plan'!$A$2:$A$304,"15 System admin",'Test Plan'!$H$2:$H$304,"Fail") | F33: =COUNTIFS('Test Plan'!$A$2:$A$304,"15 System admin",'Test Plan'!$H$2:$H$304,"Blocked") | G33: =COUNTIFS('Test Plan'!$A$2:$A$304,"15 System admin",'Test Plan'!$H$2:$H$304,"Not run") | H33: =COUNTIFS('Test Plan'!$A$2:$A$304,"15 System admin",'Test Plan'!$H$2:$H$304,"N/A")
B34: 16 REST API | C34: =COUNTIF('Test Plan'!$A$2:$A$304,"16 REST API") | D34: =COUNTIFS('Test Plan'!$A$2:$A$304,"16 REST API",'Test Plan'!$H$2:$H$304,"Pass") | E34: =COUNTIFS('Test Plan'!$A$2:$A$304,"16 REST API",'Test Plan'!$H$2:$H$304,"Fail") | F34: =COUNTIFS('Test Plan'!$A$2:$A$304,"16 REST API",'Test Plan'!$H$2:$H$304,"Blocked") | G34: =COUNTIFS('Test Plan'!$A$2:$A$304,"16 REST API",'Test Plan'!$H$2:$H$304,"Not run") | H34: =COUNTIFS('Test Plan'!$A$2:$A$304,"16 REST API",'Test Plan'!$H$2:$H$304,"N/A")
B35: 17 Cron jobs | C35: =COUNTIF('Test Plan'!$A$2:$A$304,"17 Cron jobs") | D35: =COUNTIFS('Test Plan'!$A$2:$A$304,"17 Cron jobs",'Test Plan'!$H$2:$H$304,"Pass") | E35: =COUNTIFS('Test Plan'!$A$2:$A$304,"17 Cron jobs",'Test Plan'!$H$2:$H$304,"Fail") | F35: =COUNTIFS('Test Plan'!$A$2:$A$304,"17 Cron jobs",'Test Plan'!$H$2:$H$304,"Blocked") | G35: =COUNTIFS('Test Plan'!$A$2:$A$304,"17 Cron jobs",'Test Plan'!$H$2:$H$304,"Not run") | H35: =COUNTIFS('Test Plan'!$A$2:$A$304,"17 Cron jobs",'Test Plan'!$H$2:$H$304,"N/A")
B36: 18 Regression | C36: =COUNTIF('Test Plan'!$A$2:$A$304,"18 Regression") | D36: =COUNTIFS('Test Plan'!$A$2:$A$304,"18 Regression",'Test Plan'!$H$2:$H$304,"Pass") | E36: =COUNTIFS('Test Plan'!$A$2:$A$304,"18 Regression",'Test Plan'!$H$2:$H$304,"Fail") | F36: =COUNTIFS('Test Plan'!$A$2:$A$304,"18 Regression",'Test Plan'!$H$2:$H$304,"Blocked") | G36: =COUNTIFS('Test Plan'!$A$2:$A$304,"18 Regression",'Test Plan'!$H$2:$H$304,"Not run") | H36: =COUNTIFS('Test Plan'!$A$2:$A$304,"18 Regression",'Test Plan'!$H$2:$H$304,"N/A")
B37: 19 KPIs | C37: =COUNTIF('Test Plan'!$A$2:$A$304,"19 KPIs") | D37: =COUNTIFS('Test Plan'!$A$2:$A$304,"19 KPIs",'Test Plan'!$H$2:$H$304,"Pass") | E37: =COUNTIFS('Test Plan'!$A$2:$A$304,"19 KPIs",'Test Plan'!$H$2:$H$304,"Fail") | F37: =COUNTIFS('Test Plan'!$A$2:$A$304,"19 KPIs",'Test Plan'!$H$2:$H$304,"Blocked") | G37: =COUNTIFS('Test Plan'!$A$2:$A$304,"19 KPIs",'Test Plan'!$H$2:$H$304,"Not run") | H37: =COUNTIFS('Test Plan'!$A$2:$A$304,"19 KPIs",'Test Plan'!$H$2:$H$304,"N/A")
B38: 20 Customers | C38: =COUNTIF('Test Plan'!$A$2:$A$304,"20 Customers") | D38: =COUNTIFS('Test Plan'!$A$2:$A$304,"20 Customers",'Test Plan'!$H$2:$H$304,"Pass") | E38: =COUNTIFS('Test Plan'!$A$2:$A$304,"20 Customers",'Test Plan'!$H$2:$H$304,"Fail") | F38: =COUNTIFS('Test Plan'!$A$2:$A$304,"20 Customers",'Test Plan'!$H$2:$H$304,"Blocked") | G38: =COUNTIFS('Test Plan'!$A$2:$A$304,"20 Customers",'Test Plan'!$H$2:$H$304,"Not run") | H38: =COUNTIFS('Test Plan'!$A$2:$A$304,"20 Customers",'Test Plan'!$H$2:$H$304,"N/A")
B39: 21 Data export | C39: =COUNTIF('Test Plan'!$A$2:$A$304,"21 Data export") | D39: =COUNTIFS('Test Plan'!$A$2:$A$304,"21 Data export",'Test Plan'!$H$2:$H$304,"Pass") | E39: =COUNTIFS('Test Plan'!$A$2:$A$304,"21 Data export",'Test Plan'!$H$2:$H$304,"Fail") | F39: =COUNTIFS('Test Plan'!$A$2:$A$304,"21 Data export",'Test Plan'!$H$2:$H$304,"Blocked") | G39: =COUNTIFS('Test Plan'!$A$2:$A$304,"21 Data export",'Test Plan'!$H$2:$H$304,"Not run") | H39: =COUNTIFS('Test Plan'!$A$2:$A$304,"21 Data export",'Test Plan'!$H$2:$H$304,"N/A")
B40: 22 Training & certs | C40: =COUNTIF('Test Plan'!$A$2:$A$304,"22 Training & certs") | D40: =COUNTIFS('Test Plan'!$A$2:$A$304,"22 Training & certs",'Test Plan'!$H$2:$H$304,"Pass") | E40: =COUNTIFS('Test Plan'!$A$2:$A$304,"22 Training & certs",'Test Plan'!$H$2:$H$304,"Fail") | F40: =COUNTIFS('Test Plan'!$A$2:$A$304,"22 Training & certs",'Test Plan'!$H$2:$H$304,"Blocked") | G40: =COUNTIFS('Test Plan'!$A$2:$A$304,"22 Training & certs",'Test Plan'!$H$2:$H$304,"Not run") | H40: =COUNTIFS('Test Plan'!$A$2:$A$304,"22 Training & certs",'Test Plan'!$H$2:$H$304,"N/A")
B41: 23 Dev journal | C41: =COUNTIF('Test Plan'!$A$2:$A$304,"23 Dev journal") | D41: =COUNTIFS('Test Plan'!$A$2:$A$304,"23 Dev journal",'Test Plan'!$H$2:$H$304,"Pass") | E41: =COUNTIFS('Test Plan'!$A$2:$A$304,"23 Dev journal",'Test Plan'!$H$2:$H$304,"Fail") | F41: =COUNTIFS('Test Plan'!$A$2:$A$304,"23 Dev journal",'Test Plan'!$H$2:$H$304,"Blocked") | G41: =COUNTIFS('Test Plan'!$A$2:$A$304,"23 Dev journal",'Test Plan'!$H$2:$H$304,"Not run") | H41: =COUNTIFS('Test Plan'!$A$2:$A$304,"23 Dev journal",'Test Plan'!$H$2:$H$304,"N/A")
B42: 24 Mass import | C42: =COUNTIF('Test Plan'!$A$2:$A$304,"24 Mass import") | D42: =COUNTIFS('Test Plan'!$A$2:$A$304,"24 Mass import",'Test Plan'!$H$2:$H$304,"Pass") | E42: =COUNTIFS('Test Plan'!$A$2:$A$304,"24 Mass import",'Test Plan'!$H$2:$H$304,"Fail") | F42: =COUNTIFS('Test Plan'!$A$2:$A$304,"24 Mass import",'Test Plan'!$H$2:$H$304,"Blocked") | G42: =COUNTIFS('Test Plan'!$A$2:$A$304,"24 Mass import",'Test Plan'!$H$2:$H$304,"Not run") | H42: =COUNTIFS('Test Plan'!$A$2:$A$304,"24 Mass import",'Test Plan'!$H$2:$H$304,"N/A")
B43: 25 Reset data | C43: =COUNTIF('Test Plan'!$A$2:$A$304,"25 Reset data") | D43: =COUNTIFS('Test Plan'!$A$2:$A$304,"25 Reset data",'Test Plan'!$H$2:$H$304,"Pass") | E43: =COUNTIFS('Test Plan'!$A$2:$A$304,"25 Reset data",'Test Plan'!$H$2:$H$304,"Fail") | F43: =COUNTIFS('Test Plan'!$A$2:$A$304,"25 Reset data",'Test Plan'!$H$2:$H$304,"Blocked") | G43: =COUNTIFS('Test Plan'!$A$2:$A$304,"25 Reset data",'Test Plan'!$H$2:$H$304,"Not run") | H43: =COUNTIFS('Test Plan'!$A$2:$A$304,"25 Reset data",'Test Plan'!$H$2:$H$304,"N/A")
B44: 26 Reading pane | C44: =COUNTIF('Test Plan'!$A$2:$A$304,"26 Reading pane") | D44: =COUNTIFS('Test Plan'!$A$2:$A$304,"26 Reading pane",'Test Plan'!$H$2:$H$304,"Pass") | E44: =COUNTIFS('Test Plan'!$A$2:$A$304,"26 Reading pane",'Test Plan'!$H$2:$H$304,"Fail") | F44: =COUNTIFS('Test Plan'!$A$2:$A$304,"26 Reading pane",'Test Plan'!$H$2:$H$304,"Blocked") | G44: =COUNTIFS('Test Plan'!$A$2:$A$304,"26 Reading pane",'Test Plan'!$H$2:$H$304,"Not run") | H44: =COUNTIFS('Test Plan'!$A$2:$A$304,"26 Reading pane",'Test Plan'!$H$2:$H$304,"N/A")
...

Sheet Original Functionality
B2: Original functionality (baseline before this cycle)
B4: Module / area | C4: Capabilities
B5: Tickets & service desk | C5: Multi-mailbox email intake (Graph/Gmail/IMAP) + manual create; statuses/priorities/types/categories/subcategories; custom fields; multi-policy SLA (per company + per primary CMDB device) with business calendars; shared filter engine + saved queues + ad-hoc bar; canned responses, merge, bulk actions, round-robin/load-balanced auto-assign, tags, watchers, time entries, CSAT; service catalog + attached forms + approvals; portal self-service, KB deflection, per-company branding, announcements.
B6: Assets & software | C6: Asset inventory + agent sync; types/statuses/locations; user assignment + checkout; warranty; vCenter + Intune; per-module dashboards. Software inventory + licences (qty/cost/renewal); software dashboard with drill-down.
B7: Changes | C7: CAB approvals, change calendar, risk scoring (likelihood x impact), field layout, statuses/types/priorities/impacts.
B8: Problems | C8: KEDB with ticket/change linking, notes, audit.
B9: CMDB | C9: Configuration items, classes, relationships, impact/blast-radius analysis.
B10: Contracts | C10: Suppliers + contacts, contract terms tabs, payment schedules, RFP builder (AI), renewal reminders.
B11: Knowledge base | C11: Versioning, draft>review>approve, 'was this helpful' ratings, AI webchat deflection.
B12: Forms & tasks | C12: Versioned forms + submissions; Tasks (kanban/list/calendar); Calendar; Morning checks.
B13: Visualisation | C13: Wiki (codebase docs), LMS (SCORM), Process mapper, Network mapper, Watchtower cross-module dashboard.
B14: Reporting | C14: System logs, per-module ticket dashboards, Intune reporting, ad-hoc ticket report builder (grouping + CSV).
B15: Workflow & automation | C15: Triggers/conditions/actions; outbound webhooks with delivery log + replay; time-based triggers (contract & warranty expiry).
B16: Platform & admin | C16: Analysts, teams, RBAC roles, module access, companies/multi-tenancy, OIDC SSO, MFA/TOTP, encryption key mgmt, API keys, REST API v1, branding, colours, DB verification, topology.

Sheet Added (8-11)
B2: Added this cycle (Phases 8-11, KPI, Customers, polish, export & LMS)
B4: Phase | C4: Feature | D4: What it does | E4: Key surfaces
B5: 8a | C5: SLA snapshot cache | D5: Per-ticket cached SLA state so met/breached is filterable & reportable. | E5: ticket_sla_snapshot; breach cron + close-path stamp; rebuild cron; SLA-state filter; SLA-outcome report dims
B6: 8b | C6: Scheduled & emailed reports | D6: Saved report (group-by + filters) runs on a cadence and emails CSV + summary. | E6: scheduled_report; includes/ticket_report.php; cron/scheduled_reports.php; Schedule UI
B7: 8c | C7: Executive dashboard | D7: Curated cross-module KPI view. | E7: reporting/executive/; get_exec_dashboard_data.php
B8: 9a | C8: Licence compliance | D8: Installed vs entitled true-up; over/under-deployment; renewal reminders. | E8: software/compliance/; get_licence_compliance.php; licence.expiring cron case
B9: 9b | C9: Change freeze windows | D9: Blackout periods; soft warning on schedule/approve; emergency exempt. | E9: change_freeze_windows; change-management/freeze/; calendar panel; save warning
B10: 9c | C10: CMDB-driven change risk | D10: Link affected CIs; downstream impact -> suggested risk impact. | E10: change_cmdb_objects; get_change_impact.php; Affected CIs panel
B11: 9d | C11: Contract -> asset coverage | D11: Which assets a contract covers + reverse lookup. | E11: contract_assets; Covered assets panel; get_asset_contracts.php
B12: 9e | C12: Asset lifecycle EOL | D12: EOL/disposal fields + eol_approaching reminder. | E12: assets.end_of_life_date/disposal_*; asset detail; asset.eol_approaching cron case
B13: 10a | C13: Unified audit log | D13: Read-only aggregator across module audit trails + CSV. | E13: system/audit/; get_audit_log.php
B14: 10b | C14: Backup + CSV import/export | D14: Streaming DB backup; CSV export/import for assets & users (preview>commit). | E14: system/backup/; backup_database.php; export_entity.php; import_entity.php
B15: 10e | C15: Multi-tenancy audit | D15: Closed 11 cross-company data leaks (changes/assets/problems, UI + REST). | E15: scoping fixes across change/problem/software/contract/API endpoints
... B31: Reset | C31: Reset data (wipe test data) | D31: 17 groups of records deleted while configuration survives; preview + typed phrase; CLI twin with dry-run. | E31: includes/data_reset.php; api/system/{get_reset_groups,reset_data}.php; system/reset/; scripts/wipe-test-data.php; docs/reset-data.md

Sheet Added (12-14)
B2: Added after the 8-11 cycle (Phases 12-14, plus BI export, demo history, migration and inbound webhooks)
B4: Phase | C4: Feature | D4: What it does | E4: Key surfaces
B5: 12a | C5: Collapsible reading-pane sections | D5: CMDB objects, custom fields, SLA, time and notes share one collapsible shell; each collapsed header carries a summary that still tells you something. State is remembered per section per analyst. | E5: assets/js/inbox.js (ticketSection helper); assets/css/inbox.css; localStorage ticketSection.*; pop-out overrides
B6: 12b | C6: Automatic time tracking | D6: The pane measures focused time and OFFERS it - a session is a proposal, never a posted entry. Hidden tabs and idle time past the threshold are not counted; each beat is clamped server-side. | E6: ticket_view_sessions; ticket_time_entries.source; includes/ticket_view_time.php; api/tickets/{ticket_heartbeat,resolve_view_time}.php; scripts/check-view-time.php; time_auto_* settings
B7: 12b | C7: Tracked time counts in cost KPIs | D7: Accepted tracked time feeds cost per ticket, utilisation, tickets per FTE and out-of-hours exactly like typed time; source remains a reporting label, not a filter. | E7: includes/kpi_engine.php (kpi_manual_time_filter removed)
B8: 12c | C8: Category hierarchy per ticket type | D8: A category may belong to one ticket type; NULL means every type, which is what every pre-12c category is. A type change under a scoped category clears it and says so; a named mismatch is refused. | E8: ticket_categories.ticket_type_id; includes/ticket_categories.php; get/save_ticket_category.php; TicketsService create+update; settings type picker; data_import row_checks
B9: 12c | C9: Event ticket type | D9: Joins Incident, Service Request and Question. Seeded once behind a marker so a deliberate deletion is respected. | E9: api/system/db_verify.php (ticket_type_event_seeded)
B10: 13a | C10: Customer contacts with a default | D10: A customer has many contacts, one default. customers.contact_* is KEPT as a mirror of that default and written in both directions, so exports, pickers and the importer needed no change. | E10: customer_contacts; tickets.customer_contact_id; includes/customer_contacts.php; api/customers/{get_contacts,save_contact,delete_contact,set_default_contact}.php; customers.js panel; reading-pane picker
B11: 13b | C11: Portal users linked to customers | D11: users.customer_id attributes a portal user to a customer, so their tickets arrive already attributed. Created users are passwordless and claimed via portal registration - nobody handles a password. | E11: users.customer_id; includes/customer_users.php; api/customers/{get_users,link_user,create_user}.php; self-service create_ticket; TicketsService::createTicket
B12: 14a | C12: Knowledge KPIs computed | D12: Articles created plus versions saved in the month by an author of that tier, de-duplicated per article. Playbook coverage stays manual - playbooks are not KB articles. | E12: includes/kpi_engine.php; kpi_definitions.source_status flipped to Ready in both the seed and the upgrade
B13: Export | C13: BI fact table & bundle export | D13: 40 derived KPI columns on the ticket export, mirroring the KPI engine, plus a zip bundle of related datasets with a manifest. | E13: includes/data_export.php; api/export/export_bundle.php; docs/powerbi-reporting.md
B14: Demo | C14: Reporting & KPI demo history | D14: Back-dated instrumented tickets numbered DMO-YYMM-NNNN, scaled to the install's own SLA targets, purgeable. | E14: includes/demo_reporting.php; api/system/generate_report_demo.php; system/demo-data/
B15: Migrate | C15: Migration from another helpdesk | D15: Maps a foreign CSV onto our columns then hands it to the existing importer, so there is one writer and one set of rules. Zoho Desk preset; measured aggregates carried over; KPI cutover guard. | E15: includes/data_migrate.php; includes/migrate_sources.php; system_settings.kpi_cutover_month; docs/migration.md
B16: Webhook | C16: Inbound webhooks | D16: Other systems raise tickets by POSTing to a signed endpoint, with correlation on the sender's own reference. Per-source rate limiting and delivery replay are NOT built. | E16: api/inbound/webhook.php; includes/inbound_webhook.php; system/inbound-webhooks/; docs/inbound-webhooks.md

Sheet Deferred
B2: Deferred / not built - do NOT test (no code exists)
B4: 10c - SAML SSO
B5: 10d - Native Slack/Teams/SMS notification channels
B6: 11c - Overtime <-> on-call rota cross-check
B7: 11e - TOIL (time off in lieu) balances
B8: Follow-up: per-tenant overtime settings
B9: Change freeze: no department scoping - a change carries no department, only a requester and an assignee
B10: KPI: metrics that need external SIEM / estate feeds stay manual or CSV-import (no integration built)
B11: KPI: NOC/SOC stream and QA metrics only populate once analysts set stream / record QA on tickets
B12: Customers: no per-company scoping of the customer list (shared by design, like CMDB and contracts)
